<?xml version="1.0"?>
<robot xmlns:xacro="http://www.ros.org/wiki/xacro" >

    <material name="white">
        <color rgba="1 1 1 1" />
    </material>

    <material name="orange">
        <color rgba="1 0.3 0.1 1"/>
    </material>

    <material name="blue">
        <color rgba="0.2 0.2 1 1"/>
    </material>

    <material name="black">
        <color rgba="0 0 0 1"/>
    </material>

    <material name="red">
        <color rgba="1 0 0 1"/>
    </material>
    
    <!-- สีเพิ่มเติม -->

    <material name="green">
        <color rgba="0 1 0 1"/>
    </material>

    <material name="yellow">
        <color rgba="1 1 0 1"/>
    </material>

    <material name="purple">
        <color rgba="0.5 0 0.5 1"/>
    </material>

    <material name="cyan">
        <color rgba="0 1 1 1"/>
    </material>

    <material name="gray">
        <color rgba="0.5 0.5 0.5 1"/>
    </material>


    <!-- BASE LINK -->

    <link name="base_link"/>

    <joint name="chassis_joint" type="fixed">
        <parent link="base_link"/>
        <child link="chassis"/>
        <origin xyz="0 0 0.75" rpy="0 0 0"/>
    </joint>

    <link name="chassis">
        <visual>
            <origin xyz="0 0 0.075" rpy="0 0 0"/>
            <geometry>
                <box size="0.46 0.46 0.15"/>
            </geometry>
            <material name="black"/>
        </visual>
        <collision>
            <origin xyz="0 0 0.075" rpy="0 0 0"/>
            <geometry>
                <box size="0.46 0.46 0.15"/>
            </geometry>
        </collision>
        <xacro:inertial_box mass="0.1" x="0.46" y="0.46" z="0.15">
            <origin xyz="0 0 0.075" rpy="0 0 0"/>
        </xacro:inertial_box>
    </link>
    <gazebo reference="chassis">
        <material>Gazebo/black</material>
    </gazebo>
    
    <!-- BASE_FOOTPRINT LINK -->
    <joint name="base_footprint_joint" type="fixed">
        <parent link="base_link"/>
        <child link="base_footprint"/>
        <origin xyz="0 0 0" rpy="0 0 0"/>
    </joint>

    <link name="base_footprint">
    </link>

    <!-- LEFT FRONT WHEEL -->
    <joint name="left_wheel_joint" type="continuous">
        <parent link="chassis"/>
        <child link="left_wheel"/>
        <origin xyz="0.23 0.23 0" rpy="-1.5708 0 0"/>
        <axis xyz="0 0 1"/>
        <dynamics damping="0.5" friction="0.8"/> 
    </joint>

    <link name="left_wheel">
        <visual>
            <geometry>
                <cylinder length="0.05" radius="0.125" />
            </geometry>
            <material name="purple"/>
        </visual>
        <collision>
            <geometry>
                <cylinder length="0.05" radius="0.125" />
            </geometry>
        </collision>
        <xacro:inertial_cylinder mass="0.1" length="0.05" radius="0.125">
            <origin xyz="0 0 0" rpy="0 0 0"/>
        </xacro:inertial_cylinder>
    </link>

    <gazebo reference="left_wheel">
        <material>Gazebo/purple</material>
        <mu1>0.8</mu1>
        <mu2>0.6</mu2>
        <plugin name="wheel_surface" filename="libgazebo_ros_surface_plugin.so">
            <rolling_resistance value="0.02"/>
            <friction value="0.9"/>
        </plugin>
    </gazebo>

    <!-- LEFT REAR WHEEL -->
    <joint name="left_wheel1_joint" type="continuous">
        <parent link="chassis"/>
        <child link="left_wheel1"/>
        <origin xyz="0.23 -0.23 0" rpy="-1.5708 0 0"/>
        <axis xyz="0 0 1"/>
        <dynamics damping="0.5" friction="0.8"/> 
    </joint>

    <link name="left_wheel1">
        <visual>
            <geometry>2
                <cylinder length="0.05" radius="0.125" />
            </geometry>
            <material name="purple"/>
        </visual>
        <collision>
            <geometry>
                <cylinder length="0.05" radius="0.125" />
            </geometry>
        </collision>
        <xacro:inertial_cylinder mass="0.1" length="0.05" radius="0.125">
            <origin xyz="0 0 0" rpy="0 0 0"/>
        </xacro:inertial_cylinder>
    </link>

    <gazebo reference="left_wheel1">
        <material>Gazebo/purple</material>
        <mu1>0.8</mu1>
        <mu2>0.6</mu2>
        <plugin name="wheel_surface" filename="libgazebo_ros_surface_plugin.so">
            <rolling_resistance value="0.02"/>
            <friction value="0.9"/>
        </plugin>
    </gazebo>

    <!-- RIGHT FRONT WHEEL -->
    <joint name="right_wheel_joint" type="continuous">
        <parent link="chassis"/>
        <child link="right_wheel"/>
        <origin xyz="-0.23 0.23 0" rpy="1.5708 0 0"/>
        <axis xyz="0 0 -1"/>
        <dynamics damping="0.5" friction="0.8"/> 
    </joint>

    <link name="right_wheel">
        <visual>
            <geometry>
                <cylinder length="0.05" radius="0.125" />
            </geometry>
            <material name="purple"/>
        </visual>
        <collision>
            <geometry>
                <cylinder length="0.05" radius="0.125" />
            </geometry>
        </collision>
        <xacro:inertial_cylinder mass="0.1" length="0.05" radius="0.125">
            <origin xyz="0 0 0" rpy="0 0 0"/>
        </xacro:inertial_cylinder>
    </link>

    <gazebo reference="right_wheel">
        <material>Gazebo/purple</material>
        <mu1>0.8</mu1>
        <mu2>0.6</mu2>
        <plugin name="wheel_surface" filename="libgazebo_ros_surface_plugin.so">
            <rolling_resistance value="0.02"/>
            <friction value="0.9"/>
        </plugin>
    </gazebo>

    <!-- RIGHT REAR WHEEL -->
    <joint name="right_wheel1_joint" type="continuous">
        <parent link="chassis"/>
        <child link="right_wheel1"/>
        <origin xyz="-0.23 -0.23 0" rpy="1.5708 0 0"/>
        <axis xyz="0 0 -1"/>
        <dynamics damping="0.5" friction="0.8"/> 
    </joint>

    <link name="right_wheel1">
        <visual>
            <geometry>
                <cylinder length="0.05" radius="0.125" />
            </geometry>
            <material name="purple"/>
        </visual>
        <collision>
            <geometry>
                <cylinder length="0.05" radius="0.125" />
            </geometry>
        </collision>
        <xacro:inertial_cylinder mass="0.1" length="0.05" radius="0.125">
            <origin xyz="0 0 0" rpy="0 0 0"/>
        </xacro:inertial_cylinder>
    </link>

    <gazebo reference="right_wheel1">
        <material>Gazebo/purple</material>
        <mu1>0.8</mu1>
        <mu2>0.6</mu2>
        <plugin name="wheel_surface" filename="libgazebo_ros_surface_plugin.so">
            <rolling_resistance value="0.02"/>
            <friction value="0.9"/>
        </plugin>
    </gazebo>


    <!-- CASTER WHEEL -->

    <joint name="caster_wheel_joint" type="fixed">
        <parent link="chassis"/>
        <child link="caster_wheel"/>
        <origin xyz="0 0 0" rpy="0 0 0"/>
    </joint>

    <link name="caster_wheel">
        <visual>
            <geometry>
                <sphere radius="0.0" />
            </geometry>
            <material name="blue"/>
        </visual>
        <collision>
            <geometry>
                <sphere radius="0.0" />
            </geometry>
        </collision>
        <xacro:inertial_sphere mass="0.1" radius="0.0">
            <origin xyz="0 0 0" rpy="0 0 0"/>
        </xacro:inertial_sphere>
    </link>
    <gazebo reference="caster_wheel">
        <material>Gazebo/Blue</material>
        <mu1 value="0.5"/>
        <mu2 value="0.5"/>
    </gazebo>

    <!-- GRIPPER BASE -->

    <joint name="gripper_base_joint" type="prismatic">
        <parent link="chassis"/>
        <child link="gripper_base"/>
        <origin xyz="0.1 0 0.075" rpy="0 0 0"/>
        <axis xyz="0 0 1"/>
        <limit lower="-0.25" upper="0.1" effort="10.0" velocity="0.15"/>
        <dynamics damping="0.005" friction="2.0"/>
    </joint>

    <link name="gripper_base">
        <visual>
            <origin xyz="0.23 0 0.075" rpy="0 0 0"/>
            <geometry>
                <box size="0.06 0.32 0.06"/>
            </geometry>
            <material name="black"/>
        </visual>
        <collision>
            <origin xyz="0.23 0 0.075" rpy="0 0 0"/>
            <geometry>
                <box size="0.06 0.32 0.06"/>
            </geometry>
        </collision>
        <xacro:inertial_box mass="0.05" x="0.06" y="0.33" z="0.06">
            <origin xyz="0.23 0 0.075" rpy="0 0 0"/>
        </xacro:inertial_box>
    </link>
    <gazebo reference="gripper_base">
        <material>Gazebo/black</material>
    </gazebo>

        <!-- GRIPPER RIGHT ARM -->

    <joint name="gripper_R_joint" type="prismatic">
        <parent link="gripper_base"/>
        <child link="gripper_R"/>
        <origin xyz="0.16 0.01 0.03" rpy="0 0 0"/>
        <axis xyz="0 1 0"/>
        <limit lower="0" upper="0.16" effort="10.0" velocity="0.5"/>
        <dynamics damping="0.05" friction="1.0"/>
    </joint>

    <link name="gripper_R">
        <visual>
            <origin xyz="0.16 0.01 0.03" rpy="0 0 0"/>
            <geometry>
                <box size="0.14 0.02 0.06"/>
            </geometry>
            <material name="black"/>
        </visual>
        <collision>
            <origin xyz="0.16 0.01 0.03" rpy="0 0 0"/>
            <geometry>
                <box size="0.14 0.02 0.06"/>
            </geometry>
        </collision>
        <xacro:inertial_box mass="0.05" x="0.14" y="0.02" z="0.06">
            <origin xyz="0.16 0.01 0.03" rpy="0 0 0"/>
        </xacro:inertial_box>
    </link>
    <gazebo reference="gripper_R">
        <material>Gazebo/black</material>
    </gazebo>

        <!-- GRIPPER LEFT ARM -->

    <joint name="gripper_L_joint" type="prismatic">
        <parent link="gripper_base"/>
        <child link="gripper_L"/>
        <origin xyz="0.16 -0.01 0.03" rpy="0 0 0"/>
        <axis xyz="0 -1 0"/>
        <limit lower="0" upper="0.16" effort="10.0" velocity="0.5"/>
        <dynamics damping="0.05" friction="1.0"/>
    </joint>

    <link name="gripper_L">
        <visual>
            <origin xyz="0.16 -0.01 0.03" rpy="0 0 0"/>
            <geometry>
                <box size="0.14 0.02 0.06"/>
            </geometry>
            <material name="black"/>
        </visual>
        <collision>
            <origin xyz="0.16 -0.01 0.03" rpy="0 0 0"/>
            <geometry>
                <box size="0.14 0.02 0.06"/>
            </geometry>
        </collision>
        <xacro:inertial_box mass="0.05" x="0.14" y="0.02" z="0.06">
            <origin xyz="0.16 -0.01 0.03" rpy="0 0 0"/>
        </xacro:inertial_box>
    </link>
    <gazebo reference="gripper_L">
        <material>Gazebo/black</material>
    </gazebo>

</robot>
